---
title: 前端笔试题
date: 2022-06-12 20:14:34
permalink: /pages/OKSKWSK/
categories:
  - 前端
  - 前端基础概念
tags:
  - 面试
author:
  name: WJYGRIT
  link: https://github.com/GRITWJY
---

# 前端笔试题


## 1. 时间复杂度
对于以下代码分析
```cpp
int test(int N)
{
    int i = 0;
    int cnt = 0;
    while (cnt<N)
    {
        i = i + 2;
        cnt = cnt + i;
    }
    return i;
}

```
:::details
<img :src="$withBase('/OKSKWSK/img.png')" alt="foo"/>
:::


## 2. 代码输出结果
```javascript
Promise.resolve(1)
  .then(2)
  .then(Promise.resolve(3))
  .then(console.log)
```

:::details
```
1
Promise {<fulfilled>: undefined}
```
Promise.resolve方法的参数如果是一个原始值，或者是一个不具有then方法的对象，则Promise.resolve方法返回一个新的Promise对象，状态为resolved，Promise.resolve方法的参数，会同时传给回调函数。

then方法接受的参数是函数，而如果传递的并非是一个函数，它实际上会将其解释为then(null)，这就会导致前一个Promise的结果会传递下面。


:::


## 3. 代码输出结果
```javascript
const promise1 = new Promise((resolve, reject) => {
  setTimeout(() => {
    resolve('success')
  }, 1000)
})
const promise2 = promise1.then(() => {
  throw new Error('error!!!')
})
console.log('promise1', promise1)
console.log('promise2', promise2)
setTimeout(() => {
  console.log('promise1', promise1)
  console.log('promise2', promise2)
}, 2000)

```

:::details
```
promise1 Promise {<pending>}
promise2 Promise {<pending>}

Uncaught (in promise) Error: error!!!
promise1 Promise {<fulfilled>: "success"}
promise2 Promise {<rejected>: Error: error!!}

```
:::


## 4. 代码输出结果
```javascript
Promise.resolve(1)
  .then(res => {
    console.log(res);
    return 2;
  })
  .catch(err => {
    return 3;
  })
  .then(res => {
    console.log(res);
  });

```

:::details
```
1
2
```
Promise是可以链式调用的，由于每次调用 .then 或者 .catch 都会返回一个新的 promise，从而实现了链式调用, 它并不像一般任务的链式调用一样return this。

上面的输出结果之所以依次打印出1和2，是因为resolve(1)之后走的是第一个then方法，并没有进catch里，所以第二个then中的res得到的实际上是第一个then的返回值。并且return 2会被包装成resolve(2)，被最后的then打印输出2。
:::


## 5. 代码输出结果

```javascript
Promise.resolve().then(() => {
  return new Error('error!!!')
}).then(res => {
  console.log("then: ", res)
}).catch(err => {
  console.log("catch: ", err)
})

```

:::details
```
"then: " "Error: error!!!"
```

返回任意一个非 promise 的值都会被包裹成 promise 对象，因此这里的`return new Error('error!!!')`也被包裹成了`return Promise.resolve(new Error('error!!!'))，`因此它会被then捕获而不是catch。

:::



## 6. 代码输出结果
```javascript
Promise.resolve('1')
  .then(res => {
    console.log(res)
  })
  .finally(() => {
    console.log('finally')
  })
Promise.resolve('2')
  .finally(() => {
    console.log('finally2')
  	return '我是finally2返回的值'
  })
  .then(res => {
    console.log('finally2后面的then函数', res)
  })

```

:::details
```
1
finally2
finally
finally2后面的then函数 2
```
`.finally()`一般用的很少，只要记住以下几点就可以了：

- `.finally()`方法不管Promise对象最后的状态如何都会执行
- `.finally()`方法的回调函数不接受任何的参数，也就是说你在`.finally()`函数中是无法知道Promise最终的状态是`resolved`还是`rejected`的
- 它最终返回的默认会是一个上一次的Promise对象值，不过如果抛出的是一个异常则返回异常的Promise对象。
- finally本质上是then方法的特例

`.finally()`的错误捕获：
```javascript
Promise.resolve('1')
  .finally(() => {
    console.log('finally1')
    throw new Error('我是finally中抛出的异常')
  })
  .then(res => {
    console.log('finally后面的then函数', res)
  })
  .catch(err => {
    console.log('捕获错误', err)
  })


// 'finally1'
// '捕获错误' Error: 我是finally中抛出的异常
```
:::


## 7. 代码输出结果
```javascript
async function async1() {
  console.log("async1 start");
  await async2();
  console.log("async1 end");
}
async function async2() {
  console.log("async2");
}
async1();
console.log('start')
```

:::details
```
async1 start
async2
start
async1 end
```
代码的执行过程如下：

- 1. 首先执行函数中的同步代码async1 start，之后遇到了await，它会阻塞async1后面代码的执行，因此会先去执行async2中的同步代码async2，然后跳出async1；
- 2. 跳出async1函数后，执行同步代码start；
- 3. 在一轮宏任务全部执行完之后，再来执行await后面的内容async1 end。

这里可以理解为await后面的语句相当于放到了new Promise中，下一行及之后的语句相当于放在Promise.then中。


:::
